Workbook

Sheet Resumen
A1: Base de datos de productos colombianos · Logística y trivia
A2: Datos referenciales/ilustrativos (precios, pesos, rutas, vida útil) pensados para un juego de tarjetas de trivia. Verifica los valores antes de usarlos como información comercial real.
A4: Indicadores | B4: Valor | D4: Cómo usar este archivo
A5: Productos registrados | B5: =COUNTA(Productos!A:A)-1 -> 30 | D5: • Productos: ficha de cada producto (SKU, marca, medida, referencia, conservación, tipo, tamaño, origen), como en la tarjeta de ejemplo.
A6: Tiendas registradas | B6: =COUNTA(Tiendas!A:A)-1 -> 11 | D6: • Logística: pesos, cajas, estibas, temperatura, vida útil, vehículo y ruta. Columnas con encabezado morado = fórmulas (no editar).
A7: Registros de inventario | B7: =COUNTA(Inventario!A:A)-1 -> 90 | D7: • Tiendas: cadenas y formatos, CD que las abastece, frecuencia de reabastecimiento y si tienen cuarto frío.
A8: Registros por reabastecer | B8: =COUNTIF(Inventario!J:J,"Reabastecer") -> 27 | D8: • Inventario: precio, stock y mínimo por tienda y producto. El estado y el valor se calculan solos.
A9: Valor total del inventario (COP) | B9: =SUM(Inventario!K:K) -> 125434800 | D9: • Trivia: afirmaciones Verdadero/Falso con explicación, dificultad, puntos y SKU relacionado. Listas para importar a tu sistema de tarjetas.
A10: Productos con transporte controlado | B10: =COUNTIF(Logística!J:J,"Sí") -> 12 | D10: • Encabezado azul oscuro = datos que puedes editar. Encabezado morado = calculado por fórmula.
A11: Total de afirmaciones de trivia | B11: =COUNTA(Trivia!A:A)-1 -> 166 | D11: • Las afirmaciones de trivia son texto fijo creado a partir de estos datos: si cambias un dato, actualiza la afirmación que lo usa (ver columna «Fuente del dato»).
A12: Verdaderas | B12: =COUNTIF(Trivia!D:D,"Verdadero") -> 85 | D12: • Para sacar una tarjeta: usa 'Afirmación' como frente y 'Respuesta correcta' + 'Explicación' como reverso. Filtra por 'Activa' = Sí.
A13: Falsas | B13: =COUNTIF(Trivia!D:D,"Falso") -> 81
A15: Afirmaciones por tema | B15: Cantidad
A16: Cadena de frío | B16: =COUNTIF(Trivia!B:B,A16) -> 30
A17: Paletizado y embalaje | B17: =COUNTIF(Trivia!B:B,A17) -> 30
A18: Vida útil y rotación | B18: =COUNTIF(Trivia!B:B,A18) -> 8
A19: Transporte y rutas | B19: =COUNTIF(Trivia!B:B,A19) -> 15
A20: Origen y producto | B20: =COUNTIF(Trivia!B:B,A20) -> 37
A21: Inventario en tienda | B21: =COUNTIF(Trivia!B:B,A21) -> 26
A22: Conceptos de logística | B22: =COUNTIF(Trivia!B:B,A22) -> 20
A24: Afirmaciones por dificultad | B24: Cantidad
A25: Fácil | B25: =COUNTIF(Trivia!F:F,A25) -> 82
A26: Media | B26: =COUNTIF(Trivia!F:F,A26) -> 52
A27: Difícil | B27: =COUNTIF(Trivia!F:F,A27) -> 32

Sheet Productos
A1: SKU | B1: Producto | C1: Categoría | D1: Subcategoría | E1: Descripción | F1: Marca | G1: Medida | H1: Referencia | I1: Conservación | J1: Qué tipo es | K1: Tamaño | L1: Origen (dpto.) | M1: Emoji
A2: 00219 | B2: Banano premium | C2: Frutas y verduras | D2: Frescos | E2: Banano fresco seleccionado, fuente natural de energía. | F2: Frescura | G2: 1 kg | H2: FRU-BA-001 | I2: Temperatura ambiente | J2: Fruta fresca | K2: 1 kg | L2: Antioquia (Urabá) | M2: 🍌
A3: 00220 | B3: Aguacate Hass | C3: Frutas y verduras | D3: Frescos | E3: Aguacate Hass de pulpa cremosa, cosecha nacional. | F3: Frescura | G3: 1 kg | H3: FRU-AG-002 | I3: Temperatura ambiente | J3: Fruta fresca | K3: Bolsa 1 kg | L3: Antioquia | M3: 🥑
A4: 00221 | B4: Papa criolla lavada | C4: Frutas y verduras | D4: Tubérculos | E4: Papa criolla amarilla lavada, lista para cocinar. | F4: Frescura | G4: 500 g | H4: FRU-PC-003 | I4: Lugar fresco y seco | J4: Tubérculo | K4: Bolsa 500 g | L4: Cundinamarca | M4: 🥔
A5: 00222 | B5: Plátano hartón | C5: Frutas y verduras | D5: Frescos | E5: Plátano hartón verde, ideal para patacones y sancocho. | F5: Frescura | G5: 1 kg | H5: FRU-PL-004 | I5: Temperatura ambiente | J5: Fruta fresca | K5: 1 kg | L5: Quindío | M5: 🍌
A6: 00223 | B6: Uchuva con capacho | C6: Frutas y verduras | D6: Frescos | E6: Uchuva fresca con capacho, dulce y ligeramente ácida. | F6: Frescura | G6: 250 g | H6: FRU-UC-005 | I6: Refrigerado 2–6 °C | J6: Fruta fresca | K6: Canastilla 250 g | L6: Cundinamarca | M6: 🟠
A7: 00224 | B7: Lulo | C7: Frutas y verduras | D7: Frescos | E7: Lulo fresco, base de los jugos más típicos de Colombia. | F7: Frescura | G7: 500 g | H7: FRU-LU-006 | I7: Refrigerado 7–10 °C | J7: Fruta fresca | K7: Bolsa 500 g | L7: Huila | M7: 🍊
A8: 00225 | B8: Mango Tommy | C8: Frutas y verduras | D8: Frescos | E8: Mango Tommy de pulpa firme y dulce. | F8: Frescura | G8: 1 kg | H8: FRU-MA-007 | I8: Temperatura ambiente | J8: Fruta fresca | K8: 1 kg | L8: Tolima | M8: 🥭
A9: 00226 | B9: Cebolla cabezona blanca | C9: Frutas y verduras | D9: Hortalizas | E9: Cebolla cabezona blanca seleccionada. | F9: Frescura | G9: 1 kg | H9: FRU-CE-008 | I9: Lugar fresco y seco | J9: Hortaliza | K9: Malla 1 kg | L9: Boyacá | M9: 🧅
A10: 00227 | B10: Leche entera pasteurizada | C10: Lácteos y refrigerados | D10: Leches | E10: Leche entera pasteurizada en bolsa. | F10: Colanta | G10: 1 L | H10: LAC-LE-009 | I10: Refrigerado 2–6 °C | J10: Lácteo | K10: Bolsa 1 L | L10: Antioquia | M10: 🥛
A11: 00228 | B11: Yogurt entero | C11: Lácteos y refrigerados | D11: Yogures | E11: Yogurt entero cremoso. | F11: Alpina | G11: 1 L | H11: LAC-YO-010 | I11: Refrigerado 2–6 °C | J11: Lácteo | K11: Bolsa 1 L | L11: Cundinamarca | M11: 🥛
A12: 00229 | B12: Queso campesino | C12: Lácteos y refrigerados | D12: Quesos | E12: Queso campesino fresco, suave y de sabor lácteo. | F12: Colanta | G12: 500 g | H12: LAC-QU-011 | I12: Refrigerado 2–6 °C | J12: Lácteo | K12: Bloque 500 g | L12: Antioquia | M12: 🧀
... A31: 00248 | B31: Papel higiénico | C31: Hogar y aseo | D31: Aseo personal | E31: Papel higiénico de doble hoja. | F31: Familia | G31: 12 rollos | H31: HOG-PH-030 | I31: Lugar fresco y seco | J31: Papel higiénico | K31: Paquete x 12 | L31: Antioquia | M31: 🧻

Sheet Logística
A1: SKU | B1: Producto | C1: Peso unitario (kg) | D1: Unidades por caja | E1: Peso por caja (kg) | F1: Cajas por estiba | G1: Unidades por estiba | H1: Peso neto por estiba (kg) | I1: Embalaje | J1: Transporte con temp. controlada | K1: Temp. mín (°C) | L1: Temp. máx (°C) | M1: Vida útil (días) | N1: Vehículo típico | O1: Origen de despacho | P1: CD destino | Q1: Distancia aprox. (km) | R1: Tránsito aprox. (h) | S1: Máx. niveles apilables
A2: 00219 | B2: =IFERROR(INDEX(Productos!$B:$B,MATCH($A2,Productos!$A:$A,0)),"") -> Banano premium | C2: 1 | D2: 18 | E2: =C2*D2 -> 18 | F2: 48 | G2: =D2*F2 -> 864 | H2: =E2*F2 -> 864 | I2: Caja de cartón ventilada | J2: Sí | K2: 13 | L2: 15 | M2: 7 | N2: Tractomula refrigerada | O2: Apartadó | P2: CD Medellín | Q2: 310 | R2: 7 | S2: 5
A3: 00220 | B3: =IFERROR(INDEX(Productos!$B:$B,MATCH($A3,Productos!$A:$A,0)),"") -> Aguacate Hass | C3: 1 | D3: 10 | E3: =C3*D3 -> 10 | F3: 64 | G3: =D3*F3 -> 640 | H3: =E3*F3 -> 640 | I3: Caja de cartón ventilada | J3: Sí | K3: 5 | L3: 8 | M3: 10 | N3: Camión refrigerado | O3: Jardín | P3: CD Medellín | Q3: 130 | R3: 3.5 | S3: 6
A4: 00221 | B4: =IFERROR(INDEX(Productos!$B:$B,MATCH($A4,Productos!$A:$A,0)),"") -> Papa criolla lavada | C4: 0.5 | D4: 20 | E4: =C4*D4 -> 10 | F4: 60 | G4: =D4*F4 -> 1200 | H4: =E4*F4 -> 600 | I4: Caja plástica | J4: Sí | K4: 8 | L4: 12 | M4: 20 | N4: Furgón seco | O4: Zipaquirá | P4: CD Bogotá | Q4: 60 | R4: 2 | S4: 5
A5: 00222 | B5: =IFERROR(INDEX(Productos!$B:$B,MATCH($A5,Productos!$A:$A,0)),"") -> Plátano hartón | C5: 1 | D5: 15 | E5: =C5*D5 -> 15 | F5: 40 | G5: =D5*F5 -> 600 | H5: =E5*F5 -> 600 | I5: Caja de cartón ventilada | J5: Sí | K5: 13 | L5: 15 | M5: 10 | N5: Camión refrigerado | O5: Armenia | P5: CD Cali | Q5: 190 | R5: 4 | S5: 5
A6: 00223 | B6: =IFERROR(INDEX(Productos!$B:$B,MATCH($A6,Productos!$A:$A,0)),"") -> Uchuva con capacho | C6: 0.25 | D6: 12 | E6: =C6*D6 -> 3 | F6: 120 | G6: =D6*F6 -> 1440 | H6: =E6*F6 -> 360 | I6: Canastilla plástica | J6: Sí | K6: 2 | L6: 6 | M6: 15 | N6: Camión refrigerado | O6: Fusagasugá | P6: CD Bogotá | Q6: 65 | R6: 2.5 | S6: 4
A7: 00224 | B7: =IFERROR(INDEX(Productos!$B:$B,MATCH($A7,Productos!$A:$A,0)),"") -> Lulo | C7: 0.5 | D7: 12 | E7: =C7*D7 -> 6 | F7: 100 | G7: =D7*F7 -> 1200 | H7: =E7*F7 -> 600 | I7: Caja de cartón ventilada | J7: Sí | K7: 7 | L7: 10 | M7: 12 | N7: Camión refrigerado | O7: Neiva | P7: CD Bogotá | Q7: 310 | R7: 7 | S7: 5
A8: 00225 | B8: =IFERROR(INDEX(Productos!$B:$B,MATCH($A8,Productos!$A:$A,0)),"") -> Mango Tommy | C8: 1 | D8: 10 | E8: =C8*D8 -> 10 | F8: 60 | G8: =D8*F8 -> 600 | H8: =E8*F8 -> 600 | I8: Caja de cartón ventilada | J8: Sí | K8: 10 | L8: 13 | M8: 8 | N8: Camión refrigerado | O8: Espinal | P8: CD Bogotá | Q8: 170 | R8: 3.5 | S8: 5
A9: 00226 | B9: =IFERROR(INDEX(Productos!$B:$B,MATCH($A9,Productos!$A:$A,0)),"") -> Cebolla cabezona blanca | C9: 1 | D9: 20 | E9: =C9*D9 -> 20 | F9: 36 | G9: =D9*F9 -> 720 | H9: =E9*F9 -> 720 | I9: Malla en bulto | J9: No | K9: 15 | L9: 25 | M9: 30 | N9: Furgón seco | O9: Tunja | P9: CD Bogotá | Q9: 145 | R9: 3 | S9: 4
A10: 00227 | B10: =IFERROR(INDEX(Productos!$B:$B,MATCH($A10,Productos!$A:$A,0)),"") -> Leche entera pasteurizada | C10: 1.05 | D10: 12 | E10: =C10*D10 -> 12.6 | F10: 56 | G10: =D10*F10 -> 672 | H10: =E10*F10 -> 705.6 | I10: Canasta plástica | J10: Sí | K10: 2 | L10: 6 | M10: 10 | N10: Camión refrigerado | O10: Medellín | P10: CD Bogotá | Q10: 415 | R10: 9.5 | S10: 3
A11: 00228 | B11: =IFERROR(INDEX(Productos!$B:$B,MATCH($A11,Productos!$A:$A,0)),"") -> Yogurt entero | C11: 1.05 | D11: 12 | E11: =C11*D11 -> 12.6 | F11: 60 | G11: =D11*F11 -> 720 | H11: =E11*F11 -> 756 | I11: Canasta plástica | J11: Sí | K11: 2 | L11: 6 | M11: 30 | N11: Camión refrigerado | O11: Sopó | P11: CD Cali | Q11: 480 | R11: 10 | S11: 4
A12: 00229 | B12: =IFERROR(INDEX(Productos!$B:$B,MATCH($A12,Productos!$A:$A,0)),"") -> Queso campesino | C12: 0.5 | D12: 10 | E12: =C12*D12 -> 5 | F12: 120 | G12: =D12*F12 -> 1200 | H12: =E12*F12 -> 600 | I12: Caja de cartón | J12: Sí | K12: 2 | L12: 6 | M12: 30 | N12: Camión refrigerado | O12: Medellín | P12: CD Cali | Q12: 430 | R12: 9 | S12: 5
A13: 00230 | B13: =IFERROR(INDEX(Productos!$B:$B,MATCH($A13,Productos!$A:$A,0)),"") -> Salchichas tipo Viena | C13: 0.45 | D13: 20 | E13: =C13*D13 -> 9 | F13: 80 | G13: =D13*F13 -> 1600 | H13: =E13*F13 -> 720 | I13: Caja de cartón | J13: Sí | K13: 0 | L13: 4 | M13: 60 | N13: Camión refrigerado | O13: Medellín | P13: CD Barranquilla | Q13: 690 | R13: 14 | S13: 5
... A30: 00247 | B30: =IFERROR(INDEX(Productos!$B:$B,MATCH($A30,Productos!$A:$A,0)),"") -> Galletas Saltín | C30: 0.3 | D30: 20 | E30: =C30*D30 -> 6 | F30: 110 | G30: =D30*F30 -> 2200 | H30: =E30*F30 -> 660 | I30: Caja de cartón | J30: No | K30: 15 | L30: 30 | M30: 180 | N30: Furgón seco | O30: Medellín | P30: CD Bogotá | Q30: 415 | R30: 9.5 | S30: 5
A31: 00248 | B31: =IFERROR(INDEX(Productos!$B:$B,MATCH($A31,Productos!$A:$A,0)),"") -> Papel higiénico | C31: 1.2 | D31: 4 | E31: =C31*D31 -> 4.8 | F31: 80 | G31: =D31*F31 -> 320 | H31: =E31*F31 -> 384 | I31: Termoencogible | J31: No | K31: 15 | L31: 30 | M31: N/A | N31: Tractomula con furgón seco | O31: Medellín | P31: CD Bogotá | Q31: 415 | R31: 9.5 | S31: 6

Sheet Tiendas
A1: ID tienda | B1: Tienda | C1: Cadena | D1: Formato | E1: Ciudad | F1: Departamento | G1: CD que abastece | H1: Tiempo desde CD (h) | I1: Frecuencia de reabastecimiento | J1: Cuarto frío en bodega
A2: T01 | B2: Éxito Medellín | C2: Éxito | D2: Hipermercado | E2: Medellín | F2: Antioquia | G2: CD Medellín | H2: 1 | I2: Diaria | J2: Sí
A3: T02 | B3: Jumbo Bogotá | C3: Jumbo | D3: Hipermercado | E3: Bogotá D.C. | F3: Cundinamarca | G3: CD Bogotá | H3: 1.5 | I3: Diaria | J3: Sí
A4: T03 | B4: Carulla Bogotá | C4: Carulla | D4: Supermercado premium | E4: Bogotá D.C. | F4: Cundinamarca | G4: CD Bogotá | H4: 1.5 | I4: Diaria | J4: Sí
A5: T04 | B5: Olímpica Barranquilla | C5: Olímpica | D5: Supermercado | E5: Barranquilla | F5: Atlántico | G5: CD Barranquilla | H5: 1 | I5: Diaria | J5: Sí
A6: T05 | B6: D1 Cali | C6: D1 | D6: Tienda de descuento | E6: Cali | F6: Valle del Cauca | G6: CD Cali | H6: 1.5 | I6: Cada 2 días | J6: Sí
A7: T06 | B7: Ara Medellín | C7: Ara | D7: Tienda de descuento | E7: Medellín | F7: Antioquia | G7: CD Medellín | H7: 1.5 | I7: Cada 2 días | J7: Sí
A8: T07 | B8: Makro Cali | C8: Makro | D8: Mayorista | E8: Cali | F8: Valle del Cauca | G8: CD Cali | H8: 1 | I8: Semanal | J8: Sí
A9: T08 | B9: Justo & Bueno Bogotá | C9: Justo & Bueno | D9: Tienda de descuento | E9: Bogotá D.C. | F9: Cundinamarca | G9: CD Bogotá | H9: 2 | I9: Cada 2 días | J9: No
A10: T09 | B10: Surtimax Bucaramanga | C10: Surtimax | D10: Supermercado | E10: Bucaramanga | F10: Santander | G10: CD Bogotá | H10: 9 | I10: Semanal | J10: Sí
A11: T10 | B11: Éxito Cartagena | C11: Éxito | D11: Supermercado | E11: Cartagena | F11: Bolívar | G11: CD Cartagena | H11: 1.5 | I11: Diaria | J11: Sí
A12: T11 | B12: Tienda de barrio Bogotá | C12: Tienda de barrio | D12: Tienda tradicional | E12: Bogotá D.C. | F12: Cundinamarca | G12: CD Bogotá | H12: 2 | I12: Semanal | J12: No

Sheet Inventario
A1: ID | B1: SKU | C1: Producto | D1: ID tienda | E1: Tienda | F1: Ciudad | G1: Precio (COP) | H1: Stock (und) | I1: Stock mínimo (und) | J1: Estado | K1: Valor inventario (COP)
A2: INV001 | B2: 00241 | C2: =IFERROR(INDEX(Productos!$B:$B,MATCH($B2,Productos!$A:$A,0)),"") -> Huevos AA | D2: T04 | E2: =IFERROR(INDEX(Tiendas!$B:$B,MATCH($D2,Tiendas!$A:$A,0)),"") -> Olímpica Barranquilla | F2: =IFERROR(INDEX(Tiendas!$E:$E,MATCH($D2,Tiendas!$A:$A,0)),"") -> Barranquilla | G2: 23200 | H2: 50 | I2: 40 | J2: =IF(H2<I2,"Reabastecer","OK") -> OK | K2: =G2*H2 -> 1160000
A3: INV002 | B3: 00231 | C3: =IFERROR(INDEX(Productos!$B:$B,MATCH($B3,Productos!$A:$A,0)),"") -> Pulpa de mora congelada | D3: T01 | E3: =IFERROR(INDEX(Tiendas!$B:$B,MATCH($D3,Tiendas!$A:$A,0)),"") -> Éxito Medellín | F3: =IFERROR(INDEX(Tiendas!$E:$E,MATCH($D3,Tiendas!$A:$A,0)),"") -> Medellín | G3: 9300 | H3: 214 | I3: 154 | J3: =IF(H3<I3,"Reabastecer","OK") -> OK | K3: =G3*H3 -> 1990200
A4: INV003 | B4: 00222 | C4: =IFERROR(INDEX(Productos!$B:$B,MATCH($B4,Productos!$A:$A,0)),"") -> Plátano hartón | D4: T09 | E4: =IFERROR(INDEX(Tiendas!$B:$B,MATCH($D4,Tiendas!$A:$A,0)),"") -> Surtimax Bucaramanga | F4: =IFERROR(INDEX(Tiendas!$E:$E,MATCH($D4,Tiendas!$A:$A,0)),"") -> Bucaramanga | G4: 4100 | H4: 116 | I4: 86 | J4: =IF(H4<I4,"Reabastecer","OK") -> OK | K4: =G4*H4 -> 475600
A5: INV004 | B5: 00232 | C5: =IFERROR(INDEX(Productos!$B:$B,MATCH($B5,Productos!$A:$A,0)),"") -> Arroz blanco | D5: T10 | E5: =IFERROR(INDEX(Tiendas!$B:$B,MATCH($D5,Tiendas!$A:$A,0)),"") -> Éxito Cartagena | F5: =IFERROR(INDEX(Tiendas!$E:$E,MATCH($D5,Tiendas!$A:$A,0)),"") -> Cartagena | G5: 5800 | H5: 42 | I5: 19 | J5: =IF(H5<I5,"Reabastecer","OK") -> OK | K5: =G5*H5 -> 243600
A6: INV005 | B6: 00248 | C6: =IFERROR(INDEX(Productos!$B:$B,MATCH($B6,Productos!$A:$A,0)),"") -> Papel higiénico | D6: T01 | E6: =IFERROR(INDEX(Tiendas!$B:$B,MATCH($D6,Tiendas!$A:$A,0)),"") -> Éxito Medellín | F6: =IFERROR(INDEX(Tiendas!$E:$E,MATCH($D6,Tiendas!$A:$A,0)),"") -> Medellín | G6: 23900 | H6: 174 | I6: 126 | J6: =IF(H6<I6,"Reabastecer","OK") -> OK | K6: =G6*H6 -> 4158600
A7: INV006 | B7: 00219 | C7: =IFERROR(INDEX(Productos!$B:$B,MATCH($B7,Productos!$A:$A,0)),"") -> Banano premium | D7: T06 | E7: =IFERROR(INDEX(Tiendas!$B:$B,MATCH($D7,Tiendas!$A:$A,0)),"") -> Ara Medellín | F7: =IFERROR(INDEX(Tiendas!$E:$E,MATCH($D7,Tiendas!$A:$A,0)),"") -> Medellín | G7: 4000 | H7: 41 | I7: 29 | J7: =IF(H7<I7,"Reabastecer","OK") -> OK | K7: =G7*H7 -> 164000
A8: INV007 | B8: 00231 | C8: =IFERROR(INDEX(Productos!$B:$B,MATCH($B8,Productos!$A:$A,0)),"") -> Pulpa de mora congelada | D8: T05 | E8: =IFERROR(INDEX(Tiendas!$B:$B,MATCH($D8,Tiendas!$A:$A,0)),"") -> D1 Cali | F8: =IFERROR(INDEX(Tiendas!$E:$E,MATCH($D8,Tiendas!$A:$A,0)),"") -> Cali | G8: 10200 | H8: 131 | I8: 83 | J8: =IF(H8<I8,"Reabastecer","OK") -> OK | K8: =G8*H8 -> 1336200
A9: INV008 | B9: 00240 | C9: =IFERROR(INDEX(Productos!$B:$B,MATCH($B9,Productos!$A:$A,0)),"") -> Arequipe | D9: T02 | E9: =IFERROR(INDEX(Tiendas!$B:$B,MATCH($D9,Tiendas!$A:$A,0)),"") -> Jumbo Bogotá | F9: =IFERROR(INDEX(Tiendas!$E:$E,MATCH($D9,Tiendas!$A:$A,0)),"") -> Bogotá D.C. | G9: 8600 | H9: 65 | I9: 87 | J9: =IF(H9<I9,"Reabastecer","OK") -> Reabastecer | K9: =G9*H9 -> 559000
A10: INV009 | B10: 00243 | C10: =IFERROR(INDEX(Productos!$B:$B,MATCH($B10,Productos!$A:$A,0)),"") -> Aguardiente tradicional | D10: T02 | E10: =IFERROR(INDEX(Tiendas!$B:$B,MATCH($D10,Tiendas!$A:$A,0)),"") -> Jumbo Bogotá | F10: =IFERROR(INDEX(Tiendas!$E:$E,MATCH($D10,Tiendas!$A:$A,0)),"") -> Bogotá D.C. | G10: 58700 | H10: 265 | I10: 164 | J10: =IF(H10<I10,"Reabastecer","OK") -> OK | K10: =G10*H10 -> 15555500
A11: INV010 | B11: 00246 | C11: =IFERROR(INDEX(Productos!$B:$B,MATCH($B11,Productos!$A:$A,0)),"") -> Papas fritas sabor pollo | D11: T04 | E11: =IFERROR(INDEX(Tiendas!$B:$B,MATCH($D11,Tiendas!$A:$A,0)),"") -> Olímpica Barranquilla | F11: =IFERROR(INDEX(Tiendas!$E:$E,MATCH($D11,Tiendas!$A:$A,0)),"") -> Barranquilla | G11: 5000 | H11: 17 | I11: 13 | J11: =IF(H11<I11,"Reabastecer","OK") -> OK | K11: =G11*H11 -> 85000
A12: INV011 | B12: 00236 | C12: =IFERROR(INDEX(Productos!$B:$B,MATCH($B12,Productos!$A:$A,0)),"") -> Chocolate de mesa | D12: T02 | E12: =IFERROR(INDEX(Tiendas!$B:$B,MATCH($D12,Tiendas!$A:$A,0)),"") -> Jumbo Bogotá | F12: =IFERROR(INDEX(Tiendas!$E:$E,MATCH($D12,Tiendas!$A:$A,0)),"") -> Bogotá D.C. | G12: 17200 | H12: 36 | I12: 47 | J12: =IF(H12<I12,"Reabastecer","OK") -> Reabastecer | K12: =G12*H12 -> 619200
A13: INV012 | B13: 00233 | C13: =IFERROR(INDEX(Productos!$B:$B,MATCH($B13,Productos!$A:$A,0)),"") -> Panela cuadrada | D13: T06 | E13: =IFERROR(INDEX(Tiendas!$B:$B,MATCH($D13,Tiendas!$A:$A,0)),"") -> Ara Medellín | F13: =IFERROR(INDEX(Tiendas!$E:$E,MATCH($D13,Tiendas!$A:$A,0)),"") -> Medellín | G13: 5400 | H13: 95 | I13: 52 | J13: =IF(H13<I13,"Reabastecer","OK") -> OK | K13: =G13*H13 -> 513000
... A91: INV090 | B91: 00241 | C91: =IFERROR(INDEX(Productos!$B:$B,MATCH($B91,Productos!$A:$A,0)),"") -> Huevos AA | D91: T01 | E91: =IFERROR(INDEX(Tiendas!$B:$B,MATCH($D91,Tiendas!$A:$A,0)),"") -> Éxito Medellín | F91: =IFERROR(INDEX(Tiendas!$E:$E,MATCH($D91,Tiendas!$A:$A,0)),"") -> Medellín | G91: 21500 | H91: 359 | I91: 184 | J91: =IF(H91<I91,"Reabastecer","OK") -> OK | K91: =G91*H91 -> 7718500

Sheet Trivia
A1: ID | B1: Tema | C1: Afirmación | D1: Respuesta correcta | E1: Explicación (se muestra al responder) | F1: Dificultad | G1: SKU relacionado | H1: Producto relacionado | I1: Fuente del dato | J1: Puntos | K1: Activa
A2: TRV001 | B2: Origen y producto | C2: La conservación recomendada de «Plátano hartón» es: congelado -18 °C. | D2: Falso | E2: Falso: la conservación recomendada de «Plátano hartón» es temperatura ambiente. | F2: Fácil | G2: 00222 | H2: =IF(G2="","",IFERROR(INDEX(Productos!$B:$B,MATCH(G2,Productos!$A:$A,0)),"")) -> Plátano hartón | I2: Productos · Conservación | J2: =IF(F2="Fácil",10,IF(F2="Media",20,30)) -> 10 | K2: Sí
A3: TRV002 | B3: Transporte y rutas | C3: «Arequipe» se despacha desde Sopó hacia el CD Cali. | D3: Falso | E3: Falso: «Arequipe» sale de Sopó hacia el CD Medellín (~430 km). | F3: Media | G3: 00240 | H3: =IF(G3="","",IFERROR(INDEX(Productos!$B:$B,MATCH(G3,Productos!$A:$A,0)),"")) -> Arequipe | I3: Logística · Origen de despacho y CD destino | J3: =IF(F3="Fácil",10,IF(F3="Media",20,30)) -> 20 | K3: Sí
A4: TRV003 | B4: Cadena de frío | C4: Para transportar «Queso campesino» (Colanta) se debe mantener una temperatura entre 2 °C y 6 °C. | D4: Verdadero | E4: Verdadero: el rango de transporte de «Queso campesino» es de 2 °C a 6 °C. | F4: Fácil | G4: 00229 | H4: =IF(G4="","",IFERROR(INDEX(Productos!$B:$B,MATCH(G4,Productos!$A:$A,0)),"")) -> Queso campesino | I4: Logística · Temp. transporte mín/máx | J4: =IF(F4="Fácil",10,IF(F4="Media",20,30)) -> 10 | K4: Sí
A5: TRV004 | B5: Cadena de frío | C5: «Papel higiénico» (Familia) debe transportarse congelado a -18 °C. | D5: Falso | E5: Falso: «Papel higiénico» se transporta en condiciones secas/ambiente (15–30 °C), sin cadena de frío. | F5: Fácil | G5: 00248 | H5: =IF(G5="","",IFERROR(INDEX(Productos!$B:$B,MATCH(G5,Productos!$A:$A,0)),"")) -> Papel higiénico | I5: Logística · Transporte con temp. controlada | J5: =IF(F5="Fácil",10,IF(F5="Media",20,30)) -> 10 | K5: Sí
A6: TRV005 | B6: Origen y producto | C6: «Gaseosa Colombiana» (Postobón) tiene origen en Antioquia. | D6: Verdadero | E6: Verdadero: el origen de referencia de «Gaseosa Colombiana» es Antioquia. | F6: Fácil | G6: 00242 | H6: =IF(G6="","",IFERROR(INDEX(Productos!$B:$B,MATCH(G6,Productos!$A:$A,0)),"")) -> Gaseosa Colombiana | I6: Productos · Origen | J6: =IF(F6="Fácil",10,IF(F6="Media",20,30)) -> 10 | K6: Sí
A7: TRV006 | B7: Conceptos de logística | C7: El lead time es el tiempo que transcurre entre hacer un pedido y recibirlo. | D7: Verdadero | E7: Incluye preparación, transporte y recepción. | F7: Media | H7: =IF(G7="","",IFERROR(INDEX(Productos!$B:$B,MATCH(G7,Productos!$A:$A,0)),"")) | I7: Conocimiento general | J7: =IF(F7="Fácil",10,IF(F7="Media",20,30)) -> 20 | K7: Sí
A8: TRV007 | B8: Paletizado y embalaje | C8: Una estiba de «Panela cuadrada» se arma con 60 cajas. | D8: Falso | E8: Falso: una estiba de «Panela cuadrada» lleva 40 cajas. | F8: Difícil | G8: 00233 | H8: =IF(G8="","",IFERROR(INDEX(Productos!$B:$B,MATCH(G8,Productos!$A:$A,0)),"")) -> Panela cuadrada | I8: Logística · Cajas por estiba | J8: =IF(F8="Fácil",10,IF(F8="Media",20,30)) -> 30 | K8: Sí
A9: TRV008 | B9: Paletizado y embalaje | C9: Cada caja de «Banano premium» contiene 36 unidades. | D9: Falso | E9: Falso: cada caja de «Banano premium» trae 18 unidades. | F9: Difícil | G9: 00219 | H9: =IF(G9="","",IFERROR(INDEX(Productos!$B:$B,MATCH(G9,Productos!$A:$A,0)),"")) -> Banano premium | I9: Logística · Unidades por caja | J9: =IF(F9="Fácil",10,IF(F9="Media",20,30)) -> 30 | K9: Sí
A10: TRV009 | B10: Conceptos de logística | C10: FIFO significa «primero en entrar, primero en salir». | D10: Verdadero | E10: FIFO despacha primero lo que llegó primero a la bodega. | F10: Fácil | H10: =IF(G10="","",IFERROR(INDEX(Productos!$B:$B,MATCH(G10,Productos!$A:$A,0)),"")) | I10: Conocimiento general | J10: =IF(F10="Fácil",10,IF(F10="Media",20,30)) -> 10 | K10: Sí
A11: TRV010 | B11: Inventario en tienda | C11: D1 Cali se abastece desde el CD Cali. | D11: Verdadero | E11: Verdadero: D1 Cali recibe mercancía del CD Cali. | F11: Media | H11: =IF(G11="","",IFERROR(INDEX(Productos!$B:$B,MATCH(G11,Productos!$A:$A,0)),"")) | I11: Tiendas · CD que abastece | J11: =IF(F11="Fácil",10,IF(F11="Media",20,30)) -> 20 | K11: Sí
A12: TRV011 | B12: Conceptos de logística | C12: La trazabilidad por lote permite saber de dónde viene un producto y a qué tiendas fue enviado. | D12: Verdadero | E12: Es fundamental para retiros del mercado y control de calidad. | F12: Media | H12: =IF(G12="","",IFERROR(INDEX(Productos!$B:$B,MATCH(G12,Productos!$A:$A,0)),"")) | I12: Conocimiento general | J12: =IF(F12="Fácil",10,IF(F12="Media",20,30)) -> 20 | K12: Sí
A13: TRV012 | B13: Conceptos de logística | C13: Un centro de distribución (CD) es un lugar donde el cliente final compra directamente. | D13: Falso | E13: El CD recibe, almacena y despacha a las tiendas; no vende al público. | F13: Fácil | H13: =IF(G13="","",IFERROR(INDEX(Productos!$B:$B,MATCH(G13,Productos!$A:$A,0)),"")) | I13: Conocimiento general | J13: =IF(F13="Fácil",10,IF(F13="Media",20,30)) -> 10 | K13: Sí
A14: TRV013 | B14: Conceptos de logística | C14: El prefijo 770 en un código de barras GS1 corresponde a productos registrados en Colombia. | D14: Verdadero | E14: 770 es el prefijo GS1 asignado a Colombia. | F14: Difícil | H14: =IF(G14="","",IFERROR(INDEX(Productos!$B:$B,MATCH(G14,Productos!$A:$A,0)),"")) | I14: Conocimiento general | J14: =IF(F14="Fácil",10,IF(F14="Media",20,30)) -> 30 | K14: Sí
A15: TRV014 | B15: Conceptos de logística | C15: Un producto congelado puede pasar varias horas a 25 °C y volver a congelarse sin afectar su calidad ni su inocuidad. | D15: Falso | E15: Romper la cadena de frío afecta la calidad y aumenta el riesgo microbiológico. | F15: Media | H15: =IF(G15="","",IFERROR(INDEX(Productos!$B:$B,MATCH(G15,Productos!$A:$A,0)),"")) | I15: Conocimiento general | J15: =IF(F15="Fácil",10,IF(F15="Media",20,30)) -> 20 | K15: Sí
A16: TRV015 | B16: Origen y producto | C16: «Chocolate de mesa» (Corona) tiene origen en Antioquia. | D16: Verdadero | E16: Verdadero: el origen de referencia de «Chocolate de mesa» es Antioquia. | F16: Fácil | G16: 00236 | H16: =IF(G16="","",IFERROR(INDEX(Productos!$B:$B,MATCH(G16,Productos!$A:$A,0)),"")) -> Chocolate de mesa | I16: Productos · Origen | J16: =IF(F16="Fácil",10,IF(F16="Media",20,30)) -> 10 | K16: Sí
A17: TRV016 | B17: Cadena de frío | C17: Para transportar «Leche entera pasteurizada» (Colanta) se debe mantener una temperatura entre 2 °C y 6 °C. | D17: Verdadero | E17: Verdadero: el rango de transporte de «Leche entera pasteurizada» es de 2 °C a 6 °C. | F17: Fácil | G17: 00227 | H17: =IF(G17="","",IFERROR(INDEX(Productos!$B:$B,MATCH(G17,Productos!$A:$A,0)),"")) -> Leche entera pasteurizada | I17: Logística · Temp. transporte mín/máx | J17: =IF(F17="Fácil",10,IF(F17="Media",20,30)) -> 10 | K17: Sí
A18: TRV017 | B18: Conceptos de logística | C18: El prefijo 770 en un código de barras GS1 corresponde a productos registrados en México. | D18: Falso | E18: 770 es el de Colombia; México usa 750. | F18: Difícil | H18: =IF(G18="","",IFERROR(INDEX(Productos!$B:$B,MATCH(G18,Productos!$A:$A,0)),"")) | I18: Conocimiento general | J18: =IF(F18="Fácil",10,IF(F18="Media",20,30)) -> 30 | K18: Sí
A19: TRV018 | B19: Conceptos de logística | C19: Una estiba (pallet) permite agrupar cajas para moverlas con montacargas o apilador. | D19: Verdadero | E19: Facilita el manejo, transporte y almacenamiento de carga unitizada. | F19: Fácil | H19: =IF(G19="","",IFERROR(INDEX(Productos!$B:$B,MATCH(G19,Productos!$A:$A,0)),"")) | I19: Conocimiento general | J19: =IF(F19="Fácil",10,IF(F19="Media",20,30)) -> 10 | K19: Sí
A20: TRV019 | B20: Paletizado y embalaje | C20: Una estiba de «Huevos AA» se arma con 45 cajas. | D20: Falso | E20: Falso: una estiba de «Huevos AA» lleva 30 cajas. | F20: Difícil | G20: 00241 | H20: =IF(G20="","",IFERROR(INDEX(Productos!$B:$B,MATCH(G20,Productos!$A:$A,0)),"")) -> Huevos AA | I20: Logística · Cajas por estiba | J20: =IF(F20="Fácil",10,IF(F20="Media",20,30)) -> 30 | K20: Sí
A21: TRV020 | B21: Conceptos de logística | C21: FEFO significa «primero en vencer, primero en salir». | D21: Verdadero | E21: FEFO (First Expired, First Out) prioriza despachar lo que vence antes; es clave en perecederos. | F21: Fácil | H21: =IF(G21="","",IFERROR(INDEX(Productos!$B:$B,MATCH(G21,Productos!$A:$A,0)),"")) | I21: Conocimiento general | J21: =IF(F21="Fácil",10,IF(F21="Media",20,30)) -> 10 | K21: Sí
A22: TRV021 | B22: Paletizado y embalaje | C22: Una estiba de «Aguacate Hass» se arma con 64 cajas. | D22: Verdadero | E22: Verdadero: una estiba de «Aguacate Hass» lleva 64 cajas. | F22: Difícil | G22: 00220 | H22: =IF(G22="","",IFERROR(INDEX(Productos!$B:$B,MATCH(G22,Productos!$A:$A,0)),"")) -> Aguacate Hass | I22: Logística · Cajas por estiba | J22: =IF(F22="Fácil",10,IF(F22="Media",20,30)) -> 30 | K22: Sí
A23: TRV022 | B23: Cadena de frío | C23: «Gaseosa Colombiana» (Postobón) debe transportarse congelado a -18 °C. | D23: Falso | E23: Falso: «Gaseosa Colombiana» se transporta en condiciones secas/ambiente (10–30 °C), sin cadena de frío. | F23: Fácil | G23: 00242 | H23: =IF(G23="","",IFERROR(INDEX(Productos!$B:$B,MATCH(G23,Productos!$A:$A,0)),"")) -> Gaseosa Colombiana | I23: Logística · Transporte con temp. controlada | J23: =IF(F23="Fácil",10,IF(F23="Media",20,30)) -> 10 | K23: Sí
A24: TRV023 | B24: Vida útil y rotación | C24: La vida útil estimada de «Uchuva con capacho» es de 15 días. | D24: Verdadero | E24: Verdadero: la vida útil estimada de «Uchuva con capacho» es de 15 días. | F24: Media | G24: 00223 | H24: =IF(G24="","",IFERROR(INDEX(Productos!$B:$B,MATCH(G24,Productos!$A:$A,0)),"")) -> Uchuva con capacho | I24: Logística · Vida útil (días) | J24: =IF(F24="Fácil",10,IF(F24="Media",20,30)) -> 20 | K24: Sí
A25: TRV024 | B25: Origen y producto | C25: «Leche entera pasteurizada» (Colanta) tiene origen en Cundinamarca. | D25: Falso | E25: Falso: el origen de referencia de «Leche entera pasteurizada» es Antioquia. | F25: Fácil | G25: 00227 | H25: =IF(G25="","",IFERROR(INDEX(Productos!$B:$B,MATCH(G25,Productos!$A:$A,0)),"")) -> Leche entera pasteurizada | I25: Productos · Origen | J25: =IF(F25="Fácil",10,IF(F25="Media",20,30)) -> 10 | K25: Sí
A26: TRV025 | B26: Inventario en tienda | C26: En Éxito Medellín, «Yogurt entero» tiene un stock por debajo del mínimo y requiere reabastecimiento. | D26: Verdadero | E26: Verdadero: el stock (19) es menor al mínimo (41). | F26: Media | G26: 00228 | H26: =IF(G26="","",IFERROR(INDEX(Productos!$B:$B,MATCH(G26,Productos!$A:$A,0)),"")) -> Yogurt entero | I26: Inventario · Estado | J26: =IF(F26="Fácil",10,IF(F26="Media",20,30)) -> 20 | K26: Sí
A27: TRV026 | B27: Inventario en tienda | C27: Éxito Medellín cuenta con cuarto frío en su bodega. | D27: Verdadero | E27: Verdadero: Éxito Medellín tiene cuarto frío. | F27: Fácil | H27: =IF(G27="","",IFERROR(INDEX(Productos!$B:$B,MATCH(G27,Productos!$A:$A,0)),"")) | I27: Tiendas · Cuarto frío | J27: =IF(F27="Fácil",10,IF(F27="Media",20,30)) -> 10 | K27: Sí
A28: TRV027 | B28: Origen y producto | C28: «Cebolla cabezona blanca» (Frescura) tiene origen en Boyacá. | D28: Verdadero | E28: Verdadero: el origen de referencia de «Cebolla cabezona blanca» es Boyacá. | F28: Fácil | G28: 00226 | H28: =IF(G28="","",IFERROR(INDEX(Productos!$B:$B,MATCH(G28,Productos!$A:$A,0)),"")) -> Cebolla cabezona blanca | I28: Productos · Origen | J28: =IF(F28="Fácil",10,IF(F28="Media",20,30)) -> 10 | K28: Sí
A29: TRV028 | B29: Transporte y rutas | C29: El vehículo típico para mover «Chocolatina Jet» es: furgón seco. | D29: Verdadero | E29: Verdadero: el vehículo típico para «Chocolatina Jet» es furgón seco. | F29: Media | G29: 00245 | H29: =IF(G29="","",IFERROR(INDEX(Productos!$B:$B,MATCH(G29,Productos!$A:$A,0)),"")) -> Chocolatina Jet | I29: Logística · Vehículo | J29: =IF(F29="Fácil",10,IF(F29="Media",20,30)) -> 20 | K29: Sí
A30: TRV029 | B30: Paletizado y embalaje | C30: Cada caja de «Pulpa de mora congelada» contiene 40 unidades. | D30: Falso | E30: Falso: cada caja de «Pulpa de mora congelada» trae 20 unidades. | F30: Difícil | G30: 00231 | H30: =IF(G30="","",IFERROR(INDEX(Productos!$B:$B,MATCH(G30,Productos!$A:$A,0)),"")) -> Pulpa de mora congelada | I30: Logística · Unidades por caja | J30: =IF(F30="Fácil",10,IF(F30="Media",20,30)) -> 30 | K30: Sí
A31: TRV030 | B31: Cadena de frío | C31: «Bocadillo veleño» (Frescura) no necesita transporte con temperatura controlada. | D31: Verdadero | E31: Verdadero: «Bocadillo veleño» se transporta en condiciones secas/ambiente (15–30 °C), sin cadena de frío. | F31: Fácil | G31: 00239 | H31: =IF(G31="","",IFERROR(INDEX(Productos!$B:$B,MATCH(G31,Productos!$A:$A,0)),"")) -> Bocadillo veleño | I31: Logística · Transporte con temp. controlada | J31: =IF(F31="Fácil",10,IF(F31="Media",20,30)) -> 10 | K31: Sí
A32: TRV031 | B32: Conceptos de logística | C32: Dos presentaciones distintas de un mismo producto (500 g y 1 kg) deben compartir el mismo SKU. | D32: Falso | E32: Cada presentación se registra con un SKU distinto. | F32: Fácil | H32: =IF(G32="","",IFERROR(INDEX(Productos!$B:$B,MATCH(G32,Productos!$A:$A,0)),"")) | I32: Conocimiento general | J32: =IF(F32="Fácil",10,IF(F32="Media",20,30)) -> 10 | K32: Sí
A33: TRV032 | B33: Inventario en tienda | C33: Éxito Medellín se abastece desde el CD Medellín. | D33: Verdadero | E33: Verdadero: Éxito Medellín recibe mercancía del CD Medellín. | F33: Media | H33: =IF(G33="","",IFERROR(INDEX(Productos!$B:$B,MATCH(G33,Productos!$A:$A,0)),"")) | I33: Tiendas · CD que abastece | J33: =IF(F33="Fácil",10,IF(F33="Media",20,30)) -> 20 | K33: Sí
A34: TRV033 | B34: Origen y producto | C34: «Aceite de girasol» (Gourmet) tiene origen en Boyacá. | D34: Falso | E34: Falso: el origen de referencia de «Aceite de girasol» es Valle del Cauca. | F34: Fácil | G34: 00237 | H34: =IF(G34="","",IFERROR(INDEX(Productos!$B:$B,MATCH(G34,Productos!$A:$A,0)),"")) -> Aceite de girasol | I34: Productos · Origen | J34: =IF(F34="Fácil",10,IF(F34="Media",20,30)) -> 10 | K34: Sí
A35: TRV034 | B35: Origen y producto | C35: «Aguardiente tradicional» (Antioqueño) tiene origen en Cundinamarca. | D35: Falso | E35: Falso: el origen de referencia de «Aguardiente tradicional» es Antioquia. | F35: Fácil | G35: 00243 | H35: =IF(G35="","",IFERROR(INDEX(Productos!$B:$B,MATCH(G35,Productos!$A:$A,0)),"")) -> Aguardiente tradicional | I35: Productos · Origen | J35: =IF(F35="Fácil",10,IF(F35="Media",20,30)) -> 10 | K35: Sí
A36: TRV035 | B36: Transporte y rutas | C36: El vehículo típico para mover «Mango Tommy» es: camión refrigerado. | D36: Verdadero | E36: Verdadero: el vehículo típico para «Mango Tommy» es camión refrigerado. | F36: Media | G36: 00225 | H36: =IF(G36="","",IFERROR(INDEX(Productos!$B:$B,MATCH(G36,Productos!$A:$A,0)),"")) -> Mango Tommy | I36: Logística · Vehículo | J36: =IF(F36="Fácil",10,IF(F36="Media",20,30)) -> 20 | K36: Sí
A37: TRV036 | B37: Origen y producto | C37: «Papa criolla lavada» (Frescura) tiene origen en Huila. | D37: Falso | E37: Falso: el origen de referencia de «Papa criolla lavada» es Cundinamarca. | F37: Fácil | G37: 00221 | H37: =IF(G37="","",IFERROR(INDEX(Productos!$B:$B,MATCH(G37,Productos!$A:$A,0)),"")) -> Papa criolla lavada | I37: Productos · Origen | J37: =IF(F37="Fácil",10,IF(F37="Media",20,30)) -> 10 | K37: Sí
A38: TRV037 | B38: Origen y producto | C38: «Arroz blanco» (Diana) tiene origen en Tolima. | D38: Verdadero | E38: Verdadero: el origen de referencia de «Arroz blanco» es Tolima. | F38: Fácil | G38: 00232 | H38: =IF(G38="","",IFERROR(INDEX(Productos!$B:$B,MATCH(G38,Productos!$A:$A,0)),"")) -> Arroz blanco | I38: Productos · Origen | J38: =IF(F38="Fácil",10,IF(F38="Media",20,30)) -> 10 | K38: Sí
A39: TRV038 | B39: Inventario en tienda | C39: Ara Medellín se abastece desde el CD Cali. | D39: Falso | E39: Falso: Ara Medellín recibe mercancía del CD Medellín. | F39: Media | H39: =IF(G39="","",IFERROR(INDEX(Productos!$B:$B,MATCH(G39,Productos!$A:$A,0)),"")) | I39: Tiendas · CD que abastece | J39: =IF(F39="Fácil",10,IF(F39="Media",20,30)) -> 20 | K39: Sí
A40: TRV039 | B40: Origen y producto | C40: «Café tostado y molido» (Juan Valdez) tiene origen en Huila. | D40: Verdadero | E40: Verdadero: el origen de referencia de «Café tostado y molido» es Huila. | F40: Fácil | G40: 00234 | H40: =IF(G40="","",IFERROR(INDEX(Productos!$B:$B,MATCH(G40,Productos!$A:$A,0)),"")) -> Café tostado y molido | I40: Productos · Origen | J40: =IF(F40="Fácil",10,IF(F40="Media",20,30)) -> 10 | K40: Sí
...
